<?xml version="1.0" ?>
<robot xmlns:xacro="http://ros.org/wiki/xacro">

  <xacro:include filename="$(find custom_locobot_description)/urdf/zed2.xacro"/>
  
  <xacro:macro name="custom_pan_and_tilt" params="*origin">

    <joint name="pan" type="revolute">
      <axis xyz="0 0 1"/>
      <limit
        effort="2"
        lower="${-pi/2}"
        upper="${pi/2}"
        velocity="${pi}"/>
      <xacro:insert_block name="origin"/>
      <parent
        link="${robot_name}/camera_tower_link"/>
      <child
        link="${robot_name}/pan_link"/>
      <dynamics
        friction="0.1"
        damping="0.1"/>
    </joint>

    <link name="${robot_name}/pan_link">
      <visual>
        <origin
          rpy="0 0 ${pi/2}"
          xyz="0 0 0"/>
        <geometry>
          <mesh
            filename="package://custom_locobot_description/meshes/locobot_meshes/locobot_pan.stl"
            scale="0.001 0.001 0.001"/>
        </geometry>
        <material name="interbotix_black"/>
      </visual>
      <collision>
        <origin
          rpy="0 0 ${pi/2}"
          xyz="0 0 0"/>
        <geometry>
          <mesh
            filename="package://custom_locobot_description/meshes/locobot_meshes/locobot_pan.stl"
            scale="0.001 0.001 0.001"/>
        </geometry>
      </collision>
      <inertial>
        <origin
          rpy="0 0 ${pi/2}"
          xyz="0.012 0.000496 0.018504"/>
        <mass value="0.098997"/>
        <inertia
          ixx="0.0000276300"
          ixy="0.0000000418"
          ixz="0.0000005145"
          iyy="0.0000204300"
          iyz="-0.0000000421"
          izz="0.0000276300"/>
      </inertial>
    </link>

    <gazebo reference="${robot_name}/pan_link">
      <material>Gazebo/DarkGrey</material>
      <self_collide>true</self_collide>
    </gazebo>

    <joint name="tilt" type="revolute">
      <axis xyz="0 1 0"/>
      <limit
        effort="2"
        lower="${-pi/2}"
        upper="${radians(75)}"
        velocity="${pi}"/>
      <origin
        rpy="0 0 0"
        xyz="0.025034 0 0.019"/>
      <parent
        link="${robot_name}/pan_link"/>
      <child
        link="${robot_name}/tilt_link"/>
      <dynamics
        friction="0.1"
        damping="0.1"/>
    </joint>

    <xacro:if value="${hardware_type == 'gz_classic'}">
      <ros2_control name="camera_controller" type="system">
        <hardware>
          <plugin>gazebo_ros2_control/GazeboSystem</plugin>
        </hardware>
        <joint name="pan">
          <command_interface name="position">
            <param name="min">"${-pi/2}"</param>
            <param name="max">"${pi/2}"</param>
          </command_interface>
          <state_interface name="position"/>
        </joint>
        <joint name="tilt">
          <command_interface name="position">
            <param name="min">"${-pi/2}"</param>
            <param name="max">"${radians(75)}"</param>
          </command_interface>
          <state_interface name="position"/>
        </joint>
      </ros2_control>
    </xacro:if>

    <link name="${robot_name}/tilt_link">
      <visual>
        <origin
          rpy="0 0 ${pi/2}"
          xyz="0 0 0"/>
        <geometry>
          <mesh
            filename="package://custom_locobot_description/meshes/locobot_meshes/locobot_tilt.stl"
            scale="0.001 0.001 0.001"/>
        </geometry>
        <material name="interbotix_black"/>
      </visual>
      <collision>
        <origin
          rpy="0 0 ${pi/2}"
          xyz="0 0 0"/>
        <geometry>
          <mesh
            filename="package://custom_locobot_description/meshes/locobot_meshes/locobot_tilt.stl"
            scale="0.001 0.001 0.001"/>
        </geometry>
      </collision>
      <inertial>
        <origin
          rpy="0 0 ${pi/2}"
          xyz="0.0237737000 -0.0000016331 0.0000077432"/>
        <mass value="0.019845"/>
        <inertia
          ixx="0.0000021677"
          ixy="0.0000000000"
          ixz="0.0000000001"
          iyy="0.0000063634"
          iyz="0.0000000003"
          izz="0.0000066157"/>
      </inertial>
    </link>

    <gazebo reference="${robot_name}/tilt_link">
      <material>Gazebo/DarkGrey</material>
      <self_collide>true</self_collide>
    </gazebo>

    <joint name="zed2_camera_center_joint" type="fixed">
      <origin
        rpy="0 0 0"
        xyz="0.05318 0.0175 0.000009"/>
      <parent
        link="${robot_name}/tilt_link"/>
      <child
        link="${robot_name}/zed2_camera_center"/>
    </joint>

    <xacro:zed2/>

    <gazebo reference="camera">
      <disableFixedJointLumping>true</disableFixedJointLumping>
    </gazebo>

    <xacro:zed2_gazebo/>
    
    <gazebo>
      <plugin name="ground_truth" filename="libgazebo_ros_p3d.so">
        <frameName>map</frameName>
        <bodyName>base_footprint</bodyName>
        <topicName>ground_truth_raw</topicName>
        <updateRate>30.0</updateRate>
      </plugin>
    </gazebo>

  </xacro:macro>

</robot>
